<?xml version="1.0" encoding="utf-8"?>
<!-- This URDF was automatically created by SolidWorks to URDF Exporter! Originally created by Stephen Brawner (brawner@gmail.com) 
     Commit Version: 1.6.0-1-g15f4949  Build Version: 1.6.7594.29634
     For more information, please see http://wiki.ros.org/sw_urdf_exporter -->
<robot name="arm_simulation">

  <!-- <link name="world" />

  <joint name="world_joint" type="fixed">
    <parent link="world" />
    <child link = "base_link" />
    <origin xyz="0 0 0" rpy="0 0 0" />
  </joint> -->

  <link
    name="base_link">
    <inertial>
      <origin
        xyz="2.5854E-18 0.033569 -8.8155E-18"
        rpy="0 0 0" />
      <mass
        value="0.65122" />
      <inertia
        ixx="0.00076886"
        ixy="1.7596E-20"
        ixz="4.7253E-20"
        iyy="0.00099048"
        iyz="5.5864E-20"
        izz="0.00076886" />
    </inertial>
    <visual>
      <origin
        xyz="0 0 0"
        rpy="1.57079632679 0 0" />
      <geometry>
        <mesh
          filename="package://arm_simulation/meshes/base_link.STL" />
      </geometry>
      <material
        name="">
        <color
          rgba="1 1 1 1" />
      </material>
    </visual>
    <collision>
      <origin
        xyz="0 0 0"
        rpy="1.57079632679 0 0" />
      <geometry>
        <mesh
          filename="package://arm_simulation/meshes/base_link.STL" />
      </geometry>
    </collision>
  </link>
  <link
    name="link1">
    <inertial>
      <origin
        xyz="-6.2872E-18 7.6755E-18 0.035846"
        rpy="0 0 0" />
      <mass
        value="0.37205" />
      <inertia
        ixx="0.00018192"
        ixy="1.6333E-06"
        ixz="2.68E-21"
        iyy="0.00080831"
        iyz="-7.0181E-21"
        izz="0.0007698" />
    </inertial>
    <visual>
      <origin
        xyz="0 0 0"
        rpy="0 0 0" />
      <geometry>
        <mesh
          filename="package://arm_simulation/meshes/link1.STL" />
      </geometry>
      <material
        name="">
        <color
          rgba="1 1 1 1" />
      </material>
    </visual>
    <collision>
      <origin
        xyz="0 0 0"
        rpy="0 0 0" />
      <geometry>
        <mesh
          filename="package://arm_simulation/meshes/link1.STL" />
      </geometry>
    </collision>
  </link>
  <joint
    name="joint1"
    type="revolute">
    <origin
      xyz="0 0 0.074"
      rpy="0 0 0" />
    <parent
      link="base_link" />
    <child
      link="link1" />
    <axis
      xyz="0 0 1" />
    <limit
      lower="-3.14"
      upper="3.14"
      effort="2"
      velocity="0" />
  </joint>
  <link
    name="link2">
    <inertial>
      <origin
        xyz="0.00027312 -6.8025E-07 0.11528"
        rpy="0 0 0" />
      <mass
        value="0.46302" />
      <inertia
        ixx="0.0050956"
        ixy="1.5226E-06"
        ixz="-2.4094E-05"
        iyy="0.0057069"
        iyz="6.0009E-08"
        izz="0.00074387" />
    </inertial>
    <visual>
      <origin
        xyz="0 0 0"
        rpy="0 0 0" />
      <geometry>
        <mesh
          filename="package://arm_simulation/meshes/link2.STL" />
      </geometry>
      <material
        name="">
        <color
          rgba="1 1 1 1" />
      </material>
    </visual>
    <collision>
      <origin
        xyz="0 0 0"
        rpy="0 0 0" />
      <geometry>
        <mesh
          filename="package://arm_simulation/meshes/link2.STL" />
      </geometry>
    </collision>
  </link>
  <joint
    name="joint2"
    type="revolute">
    <origin
      xyz="-0.089 0.00023207 0.042"
      rpy="0.30054 -0.00073734 -0.00022852" />
    <parent
      link="link1" />
    <child
      link="link2" />
    <axis
      xyz="-1 0.0024907 0" />
    <limit
      lower="-1.57"
      upper="1.57"
      effort="2"
      velocity="0" />
  </joint>
  <link
    name="link3">
    <inertial>
      <origin
        xyz="-0.0046535 0.020103 0.038177"
        rpy="0 0 0" />
      <mass
        value="0.06371" />
      <inertia
        ixx="9.6305E-05"
        ixy="2.2401E-05"
        ixz="2.2964E-05"
        iyy="9.2394E-05"
        iyz="-3.1351E-05"
        izz="6.149E-05" />
    </inertial>
    <visual>
      <origin
        xyz="0 0 0"
        rpy="0 0 0" />
      <geometry>
        <mesh
          filename="package://arm_simulation/meshes/link3.STL" />
      </geometry>
      <material
        name="">
        <color
          rgba="1 1 1 1" />
      </material>
    </visual>
    <collision>
      <origin
        xyz="0 0 0"
        rpy="0 0 0" />
      <geometry>
        <mesh
          filename="package://arm_simulation/meshes/link3.STL" />
      </geometry>
    </collision>
  </link>
  <joint
    name="joint3"
    type="revolute">
    <origin
      xyz="0.05725 -0.00014259 0.2789"
      rpy="0.79723 -0.0016401 3.1407" />
    <parent
      link="link2" />
    <child
      link="link3" />
    <axis
      xyz="1 -0.0022925 0" />
    <limit
      lower="-1.57"
      upper="1.57"
      effort="2"
      velocity="0" />
  </joint>
  <link
    name="link4">
    <inertial>
      <origin
        xyz="0 -0.0016144 0.1471"
        rpy="0 0 0" />
      <mass
        value="0.41614" />
      <inertia
        ixx="0.0046604"
        ixy="5.421E-20"
        ixz="-2.0329E-20"
        iyy="0.004614"
        iyz="-5.9856E-05"
        izz="0.00017165" />
    </inertial>
    <visual>
      <origin
        xyz="0 0 0"
        rpy="0 0 0" />
      <geometry>
        <mesh
          filename="package://arm_simulation/meshes/link4.STL" />
      </geometry>
      <material
        name="">
        <color
          rgba="1 1 1 1" />
      </material>
    </visual>
    <collision>
      <origin
        xyz="0 0 0"
        rpy="0 0 0" />
      <geometry>
        <mesh
          filename="package://arm_simulation/meshes/link4.STL" />
      </geometry>
    </collision>
  </link>
  <joint
    name="joint4"
    type="revolute">
    <origin
      xyz="-0.031631 0.052087 0.064988"
      rpy="0.7035 1.3411 2.2852" />
    <parent
      link="link3" />
    <child
      link="link4" />
    <axis
      xyz="0 0 1" />
    <limit
      lower="-3.14"
      upper="3.14"
      effort="2"
      velocity="0" />
  </joint>
  <link
    name="link5">
    <inertial>
      <origin
        xyz="0.0026601 0.00039794 0.012151"
        rpy="0 0 0" />
      <mass
        value="0.030074" />
      <inertia
        ixx="1.6785E-05"
        ixy="-2.2863E-07"
        ixz="4.4532E-06"
        iyy="1.8279E-05"
        iyz="6.6617E-07"
        izz="1.2072E-05" />
    </inertial>
    <visual>
      <origin
        xyz="0 0 0"
        rpy="0 0 0" />
      <geometry>
        <mesh
          filename="package://arm_simulation/meshes/link5.STL" />
      </geometry>
      <material
        name="">
        <color
          rgba="1 1 1 1" />
      </material>
    </visual>
    <collision>
      <origin
        xyz="0 0 0"
        rpy="0 0 0" />
      <geometry>
        <mesh
          filename="package://arm_simulation/meshes/link5.STL" />
      </geometry>
    </collision>
  </link>
  <joint
    name="joint5"
    type="revolute">
    <origin
      xyz="0 -0.034 0.2684"
      rpy="-0.0364343502514425 -0.00544912780563413 -1.71919063956753" />
    <parent
      link="link4" />
    <child
      link="link5" />
    <axis
      xyz="-0.999983629434664 0.00154627583027758 0.00550907376364283" />
    <limit
      lower="-1.57"
      upper="1.57"
      effort="2"
      velocity="0" />
  </joint>
</robot>