<?xml version="1.0" encoding="utf-8"?>
<robot xmlns:xacro="http://www.ros.org/wiki/xacro" name="manipulator">
<!-- This URDF was automatically created by SolidWorks to URDF Exporter! Originally created by Stephen Brawner (brawner@gmail.com) 
     Commit Version: 1.6.0-1-g15f4949  Build Version: 1.6.7594.29634
     For more information, please see http://wiki.ros.org/sw_urdf_exporter -->

<xacro:property name="M_PI" value="3.1415926535897931" />

  <link name="base_link">
    <!-- <inertial>
      <origin
        xyz="2.095325E-5 -4.245919E-6 4.2420025E-2"
        rpy="${radians(-0.069)} ${radians(-0.103)} ${radians(90.167)}" /> 
      <mass
        value="0.325378" />
      <inertia
        ixx="4.8663191E-4"
        ixy="2.9908669E-8"
        ixz="-2.25669762E-7"
        iyy="4.7623896E-4"
        iyz="1.8332926E-7"
        izz="6.2905340E-4" />
    </inertial> -->
    <visual>
      <origin
        xyz="0 0 0"
        rpy="${M_PI/2} 0 0" />
      <geometry>
        <mesh
          filename="package://arm_simulation/meshes/base_link.STL" />
      </geometry>
      <material name="">
        <color rgba="1 1 1 1" />
      </material>
    </visual>
    <collision>
      <origin
        xyz="0 0 0"
        rpy="${M_PI/2} 0 0" />
      <geometry>
        <mesh
          filename="package://arm_simulation/meshes/base_link.STL" />
      </geometry>
    </collision>
  </link>
  <link name="link1">
    <inertial>
      <origin
        xyz="-6.2872E-18 7.6755E-18 0.035846"
        rpy="0 0 0" />
      <mass value="0.37205" />
      <inertia
        ixx="0.00018192"
        ixy="1.6333E-06"
        ixz="2.68E-21"
        iyy="0.00080831"
        iyz="-7.0181E-21"
        izz="0.0007698" />
    </inertial>
    <visual>
      <origin
        xyz="0 0 0"
        rpy="0 0 0" />
      <geometry>
        <mesh
          filename="package://arm_simulation/meshes/link1.STL" />
      </geometry>
      <material name="">
        <color rgba="1 1 1 1" />
      </material>
    </visual>
    <collision>
      <origin
        xyz="0 0 0"
        rpy="0 0 0" />
      <geometry>
        <mesh
          filename="package://arm_simulation/meshes/link1.STL" />
      </geometry>
    </collision>
  </link>
  <joint name="joint1" type="revolute">
    <origin
      xyz="0 0 0.074"
      rpy="0 0 0" />
    <parent link="base_link" />
    <child link="link1" />
    <axis xyz="0 0 1" />
    <limit
      lower="-3.14"
      upper="3.14"
      effort="2"
      velocity="0" />
  </joint>
  <link name="link2">
    <inertial>
      <origin
        xyz="0.00027312 -6.8025E-07 0.11528"
        rpy="0 0 0" />
      <mass value="0.46302" />
      <inertia
        ixx="0.0050956"
        ixy="1.5226E-06"
        ixz="-2.4094E-05"
        iyy="0.0057069"
        iyz="6.0009E-08"
        izz="0.00074387" />
    </inertial>
    <visual>
      <origin
        xyz="0 0 0"
        rpy="0 0 0" />
      <geometry>
        <mesh
          filename="package://arm_simulation/meshes/link2.STL" />
      </geometry>
      <material name="">
        <color rgba="1 1 1 1" />
      </material>
    </visual>
    <collision>
      <origin
        xyz="0 0 0"
        rpy="0 0 0" />
      <geometry>
        <mesh
          filename="package://arm_simulation/meshes/link2.STL" />
      </geometry>
    </collision>
  </link>
  <joint name="joint2" type="revolute">
    <origin
      xyz="-0.089 0.00023207 0.042"
      rpy="0.30054 -0.00073734 -0.00022852" />
    <parent link="link1" />
    <child link="link2" />
    <axis xyz="-1 0.0024907 0" />
    <limit
      lower="-1.57"
      upper="1.57"
      effort="2"
      velocity="0" />
  </joint>
  <link name="link3">
    <inertial>
      <origin
        xyz="-0.0046535 0.020103 0.038177"
        rpy="0 0 0" />
      <mass value="0.06371" />
      <inertia
        ixx="9.6305E-05"
        ixy="2.2401E-05"
        ixz="2.2964E-05"
        iyy="9.2394E-05"
        iyz="-3.1351E-05"
        izz="6.149E-05" />
    </inertial>
    <visual>
      <origin
        xyz="0 0 0"
        rpy="0 0 0" />
      <geometry>
        <mesh
          filename="package://arm_simulation/meshes/link3.STL" />
      </geometry>
      <material name="">
        <color rgba="1 1 1 1" />
      </material>
    </visual>
    <collision>
      <origin
        xyz="0 0 0"
        rpy="0 0 0" />
      <geometry>
        <mesh
          filename="package://arm_simulation/meshes/link3.STL" />
      </geometry>
    </collision>
  </link>
  <joint name="joint3" type="revolute">
    <origin
      xyz="0.05725 -0.00014259 0.2789"
      rpy="0.79723 -0.0016401 3.1407" />
    <parent link="link2" />
    <child link="link3" />
    <axis xyz="1 -0.0022925 0" />
    <limit
      lower="-1.57"
      upper="1.57"
      effort="2"
      velocity="0" />
  </joint>
  <link name="link4">
    <inertial>
      <origin
        xyz="0 -0.0016144 0.1471"
        rpy="0 0 0" />
      <mass value="0.41614" />
      <inertia
        ixx="0.0046604"
        ixy="5.421E-20"
        ixz="-2.0329E-20"
        iyy="0.004614"
        iyz="-5.9856E-05"
        izz="0.00017165" />
    </inertial>
    <visual>
      <origin
        xyz="0 0 0"
        rpy="0 0 0" />
      <geometry>
        <mesh
          filename="package://arm_simulation/meshes/link4.STL" />
      </geometry>
      <material name="">
        <color rgba="1 1 1 1" />
      </material>
    </visual>
    <collision>
      <origin
        xyz="0 0 0"
        rpy="0 0 0" />
      <geometry>
        <mesh
          filename="package://arm_simulation/meshes/link4.STL" />
      </geometry>
    </collision>
  </link>
  <joint name="joint4" type="revolute">
    <origin
      xyz="-0.031631 0.052087 0.064988"
      rpy="0.7035 1.3411 2.2852" />
    <parent link="link3" />
    <child link="link4" />
    <axis xyz="0 0 1" />
    <limit
      lower="-3.14"
      upper="3.14"
      effort="2"
      velocity="0" />
  </joint>
  <link name="link5">
    <inertial>
      <origin
        xyz="0.0026601 0.00039794 0.012151"
        rpy="0 0 0" />
      <mass value="0.030074" />
      <inertia
        ixx="1.6785E-05"
        ixy="-2.2863E-07"
        ixz="4.4532E-06"
        iyy="1.8279E-05"
        iyz="6.6617E-07"
        izz="1.2072E-05" />
    </inertial>
    <visual>
      <origin
        xyz="0 0 0"
        rpy="0 0 0" />
      <geometry>
        <mesh
          filename="package://arm_simulation/meshes/link5.STL" />
      </geometry>
      <material name="">
        <color rgba="1 1 1 1" />
      </material>
    </visual>
    <collision>
      <origin
        xyz="0 0 0"
        rpy="0 0 0" />
      <geometry>
        <mesh
          filename="package://arm_simulation/meshes/link5.STL" />
      </geometry>
    </collision>
  </link>
  <joint name="joint5" type="revolute">
    <origin
      xyz="0 -0.034 0.2684"
      rpy="-0.0364343502514425 -0.00544912780563413 -1.71919063956753" />
    <parent link="link4" />
    <child link="link5" />
    <axis xyz="-0.999983629434664 0.00154627583027758 0.00550907376364283" />
    <limit
      lower="-1.57"
      upper="1.57"
      effort="2"
      velocity="0" />
  </joint>

  <!-- <transmission name="trans_joint1">
      <type>transmission_interface/SimpleTransmission</type>
      <joint name="joint1">
          <hardwareInterface>hardware_interface/PositionJointInterface</hardwareInterface>
      </joint>
      <actuator name="joint1_motor">
          <hardwareInterface>hardware_interface/PositionJointInterface</hardwareInterface>
          <mechanicalReduction>1</mechanicalReduction>
      </actuator>
  </transmission>
  <transmission name="trans_joint2">
      <type>transmission_interface/SimpleTransmission</type>
      <joint name="joint2">
          <hardwareInterface>hardware_interface/PositionJointInterface</hardwareInterface>
      </joint>
      <actuator name="joint2_motor">
          <hardwareInterface>hardware_interface/PositionJointInterface</hardwareInterface>
          <mechanicalReduction>1</mechanicalReduction>
      </actuator>
  </transmission>
  <transmission name="trans_joint3">
      <type>transmission_interface/SimpleTransmission</type>
      <joint name="joint3">
          <hardwareInterface>hardware_interface/PositionJointInterface</hardwareInterface>
      </joint>
      <actuator name="joint3_motor">
          <hardwareInterface>hardware_interface/PositionJointInterface</hardwareInterface>
          <mechanicalReduction>1</mechanicalReduction>
      </actuator>
  </transmission>
  <transmission name="trans_joint4">
      <type>transmission_interface/SimpleTransmission</type>
      <joint name="joint4">
          <hardwareInterface>hardware_interface/PositionJointInterface</hardwareInterface>
      </joint>
      <actuator name="joint4_motor">
          <hardwareInterface>hardware_interface/PositionJointInterface</hardwareInterface>
          <mechanicalReduction>1</mechanicalReduction>
      </actuator>
  </transmission>
  <transmission name="trans_joint5">
      <type>transmission_interface/SimpleTransmission</type>
      <joint name="joint5">
          <hardwareInterface>hardware_interface/PositionJointInterface</hardwareInterface>
      </joint>
      <actuator name="joint5_motor">
          <hardwareInterface>hardware_interface/PositionJointInterface</hardwareInterface>
          <mechanicalReduction>1</mechanicalReduction>
      </actuator>
  </transmission> -->

</robot>